Workbook
Name HL: '[1]LTP 18-Aug-25'!#REF!
Name HL: '[2]LTP_24-Mar-2025'!#REF!
Name HL: 'LTP 21-Sep-26'!#REF!
Name Holiday: #REF!

Sheet LTP 21-Sep-26
G1: Pending Effort (in Hours) | K1: 21-Sep-2026 :: Addressing Plan | W1: 14-Sep-2026 :: Addressing Plan | BH1: Verification
A2: Market | B2: DR | C2: BR_ID | D2: BR_Name | E2: Driven Km | F2: Drive Details | G2: Source Prep | H2: HLA | I2: ADC | J2: MPRA | K2: Naming QA Acceptance | L2: Source Prep Start Date | M2: Source Prep End Date | N2: HLA Start date | O2: HLA End Date | P2: ADC Start Date | Q2: ADC End Date | R2: DC2 | S2: Building Delivery Date | T2: MPRA Start Date | U2: MPRA End Date | W2: Naming QA Acceptance | X2: Source Prep Start Date | Y2: Source Prep End Date | Z2: HLA Start date | AA2: HLA End Date | AB2: ADC Start Date | AC2: ADC End Date | AD2: DC2 | AE2: Building Delivery Date | AF2: MPRA Start Date | AG2: MPRA End Date | AZ2: Holiday List | BH2: Naming QA Acceptance | BI2: Source Prep Start Date | BJ2: Source Prep End Date | BK2: HLA Start date | BL2: HLA End Date | BM2: ADC Start Date | BN2: ADC End Date | BO2: DC2 | BP2: Building Delivery Date | BQ2: MPRA Start Date | BR2: MPRA End Date
A3: Brazil_P2 | B3: BRDRSP_P2 | C3: kh.br.sa.bra.08_A | D3: São Paulo | E3: 34714 | F3: Post-drive | J3: 100 | K3: 46022 | L3: - | M3: - | N3: 46028 | O3: 46031 | P3: 46032 | Q3: 46079 | R3: 46193 | S3: Available | T3: 46195 | U3: 46288 | W3: 46022 | X3: - | Y3: - | Z3: 46028 | AA3: 46031 | AB3: 46032 | AC3: 46079 | AD3: 46193 | AE3: Available | AF3: 46195 | AG3: 46288 | AZ3: 46023 | BA3: Holiday | BH3: =IFERROR(K3-W3,"0") -> 0 | BI3: =IFERROR(L3-X3,"0") -> 0 | BJ3: =IFERROR(M3-Y3,"0") -> 0 | BK3: =IFERROR(N3-Z3,"0") -> 0 | BL3: =IFERROR(O3-AA3,"0") -> 0 | BM3: =IFERROR(P3-AB3,"0") -> 0 | BN3: =IFERROR(Q3-AC3,"0") -> 0 | BO3: =IFERROR(R3-AD3,"0") -> 0 | ... BR3: =IFERROR(U3-AG3,"0") -> 0
A4: Brazil_P2 | B4: BRDRSP_P2 | C4: kh.br.sa.bra.08_C | D4: Campinas | E4: 23453 | F4: Post-drive | J4: 8864 | K4: 46029 | L4: - | M4: - | N4: 46031 | O4: 46034 | P4: 46043 | Q4: 46064 | R4: 46243 | S4: Available | T4: 46263 | U4: 46320 | W4: 46029 | X4: - | Y4: - | Z4: 46031 | AA4: 46034 | AB4: 46043 | AC4: 46064 | AD4: 46243 | AE4: Available | AF4: 46263 | AG4: 46320 | AZ4: 46036 | BA4: Holiday | BH4: =IFERROR(K4-W4,"0") -> 0 | BI4: =IFERROR(L4-X4,"0") -> 0 | BJ4: =IFERROR(M4-Y4,"0") -> 0 | BK4: =IFERROR(N4-Z4,"0") -> 0 | BL4: =IFERROR(O4-AA4,"0") -> 0 | BM4: =IFERROR(P4-AB4,"0") -> 0 | BN4: =IFERROR(Q4-AC4,"0") -> 0 | BO4: =IFERROR(R4-AD4,"0") -> 0 | ... BR4: =IFERROR(U4-AG4,"0") -> 0
A5: Brazil_P2 | B5: BRDRSP_P2 | C5: kh.br.sa.bra.08_D | D5: Ribeirão Preto | E5: 23151 | F5: Post-drive | J5: 14181 | K5: 46041 | L5: - | M5: - | N5: 46047 | O5: 46051 | P5: 46052 | Q5: 46081 | R5: 46271 | S5: Available | T5: 46298 | U5: 46348 | W5: 46041 | X5: - | Y5: - | Z5: 46047 | AA5: 46051 | AB5: 46052 | AC5: 46081 | AD5: 46271 | AE5: Available | AF5: 46280 | AG5: 46348 | AZ5: 46048 | BA5: Holiday | BH5: =IFERROR(K5-W5,"0") -> 0 | BI5: =IFERROR(L5-X5,"0") -> 0 | BJ5: =IFERROR(M5-Y5,"0") -> 0 | BK5: =IFERROR(N5-Z5,"0") -> 0 | BL5: =IFERROR(O5-AA5,"0") -> 0 | BM5: =IFERROR(P5-AB5,"0") -> 0 | BN5: =IFERROR(Q5-AC5,"0") -> 0 | BO5: =IFERROR(R5-AD5,"0") -> 0 | ... BR5: =IFERROR(U5-AG5,"0") -> 0
A6: Brazil_P2 | B6: BRDRSP_P2 | C6: kh.br.sa.bra.08_B | D6: São José dos Campos | E6: 26018 | F6: Post-drive | J6: 14977 | K6: 46049 | L6: - | M6: - | N6: 46056 | O6: 46060 | P6: 46068 | Q6: 46093 | R6: 46283 | S6: Available | T6: 46300 | U6: 46353 | W6: 46049 | X6: - | Y6: - | Z6: 46056 | AA6: 46060 | AB6: 46068 | AC6: 46093 | AD6: 46283 | AE6: Available | AF6: 46284 | AG6: 46353 | AZ6: 46115 | BA6: Holiday | BH6: =IFERROR(K6-W6,"0") -> 0 | BI6: =IFERROR(L6-X6,"0") -> 0 | BJ6: =IFERROR(M6-Y6,"0") -> 0 | BK6: =IFERROR(N6-Z6,"0") -> 0 | BL6: =IFERROR(O6-AA6,"0") -> 0 | BM6: =IFERROR(P6-AB6,"0") -> 0 | BN6: =IFERROR(Q6-AC6,"0") -> 0 | BO6: =IFERROR(R6-AD6,"0") -> 0 | ... BR6: =IFERROR(U6-AG6,"0") -> 0
A7: Brazil_P2 | B7: BRDRRIO_P2 | C7: kh.br.sa.bra.11_A | D7: Rio de Janeiro | E7: 14299 | F7: Post-drive | J7: 3816.1 | K7: 46051 | L7: - | M7: - | N7: 46059 | O7: 46072 | P7: 46081 | Q7: 46105 | R7: 46210 | S7: Available | T7: 46245 | U7: 46293 | W7: 46051 | X7: - | Y7: - | Z7: 46059 | AA7: 46072 | AB7: 46081 | AC7: 46105 | AD7: 46210 | AE7: Available | AF7: 46245 | AG7: 46293 | AZ7: 46143 | BA7: Holiday | BH7: =IFERROR(K7-W7,"0") -> 0 | BI7: =IFERROR(L7-X7,"0") -> 0 | BJ7: =IFERROR(M7-Y7,"0") -> 0 | BK7: =IFERROR(N7-Z7,"0") -> 0 | BL7: =IFERROR(O7-AA7,"0") -> 0 | BM7: =IFERROR(P7-AB7,"0") -> 0 | BN7: =IFERROR(Q7-AC7,"0") -> 0 | BO7: =IFERROR(R7-AD7,"0") -> 0 | ... BR7: =IFERROR(U7-AG7,"0") -> 0
A8: Brazil_P2 | B8: BRDRRIO_P2 | C8: kh.br.sa.bra.11_B | D8: Campos dos Goytacazes | E8: 18163 | F8: Post-drive | J8: 8329 | K8: 46053 | L8: - | M8: - | N8: 46072 | O8: 46074 | P8: 46082 | Q8: 46107 | R8: 46215 | S8: Available | T8: 46222 | U8: 46307 | W8: 46053 | X8: - | Y8: - | Z8: 46072 | AA8: 46074 | AB8: 46082 | AC8: 46107 | AD8: 46215 | AE8: Available | AF8: 46222 | AG8: 46307 | AZ8: 46169 | BA8: Holiday | BH8: =IFERROR(K8-W8,"0") -> 0 | BI8: =IFERROR(L8-X8,"0") -> 0 | BJ8: =IFERROR(M8-Y8,"0") -> 0 | BK8: =IFERROR(N8-Z8,"0") -> 0 | BL8: =IFERROR(O8-AA8,"0") -> 0 | BM8: =IFERROR(P8-AB8,"0") -> 0 | BN8: =IFERROR(Q8-AC8,"0") -> 0 | BO8: =IFERROR(R8-AD8,"0") -> 0 | ... BR8: =IFERROR(U8-AG8,"0") -> 0
A9: Brazil_P2 | B9: BRDRRIO_P2 | C9: kh.br.sa.bra.11_C | D9: Vitória | E9: 7469 | F9: Post-drive | J9: 4314 | K9: 46059 | L9: - | M9: - | N9: 46078 | O9: 46079 | P9: 46090 | Q9: 46111 | R9: 46224 | S9: Available | T9: 46247 | U9: 46301 | W9: 46059 | X9: - | Y9: - | Z9: 46078 | AA9: 46079 | AB9: 46090 | AC9: 46111 | AD9: 46224 | AE9: Available | AF9: 46247 | AG9: 46301 | AZ9: 46175 | BA9: Holiday | BH9: =IFERROR(K9-W9,"0") -> 0 | BI9: =IFERROR(L9-X9,"0") -> 0 | BJ9: =IFERROR(M9-Y9,"0") -> 0 | BK9: =IFERROR(N9-Z9,"0") -> 0 | BL9: =IFERROR(O9-AA9,"0") -> 0 | BM9: =IFERROR(P9-AB9,"0") -> 0 | BN9: =IFERROR(Q9-AC9,"0") -> 0 | BO9: =IFERROR(R9-AD9,"0") -> 0 | ... BR9: =IFERROR(U9-AG9,"0") -> 0
A10: Brazil_P2 | B10: BRDRNE_P2 | C10: kh.br.sa.bra.16 | D10: Salvador | E10: 23933 | F10: Full-drive | J10: 11303 | K10: 46075 | L10: 45607 | M10: 45627 | N10: 46092 | O10: 46105 | P10: 46107 | Q10: 46113 | R10: 46299 | S10: Available | T10: 46303 | U10: 46369 | W10: 46075 | X10: 45607 | Y10: 45627 | Z10: 46092 | AA10: 46105 | AB10: 46107 | AC10: 46113 | AD10: 46299 | AE10: Available | AF10: 46300 | AG10: 46369 | AZ10: 46249 | BA10: Holiday | BH10: =IFERROR(K10-W10,"0") -> 0 | BI10: =IFERROR(L10-X10,"0") -> 0 | BJ10: =IFERROR(M10-Y10,"0") -> 0 | BK10: =IFERROR(N10-Z10,"0") -> 0 | BL10: =IFERROR(O10-AA10,"0") -> 0 | BM10: =IFERROR(P10-AB10,"0") -> 0 | BN10: =IFERROR(Q10-AC10,"0") -> 0 | BO10: =IFERROR(R10-AD10,"0") -> 0 | ... BR10: =IFERROR(U10-AG10,"0") -> 0
A11: Brazil_P2 | B11: BRDRNE_P2 | C11: kh.br.sa.bra.17 | D11: Recife | E11: 22668 | F11: Full-drive | J11: 7608 | K11: 46091 | L11: 45614 | M11: 45627 | N11: 46102 | O11: 46107 | P11: 46107 | Q11: 46168 | R11: 46307 | S11: Available | T11: 46336 | U11: 46378 | W11: 46091 | X11: 45614 | Y11: 45627 | Z11: 46102 | AA11: 46107 | AB11: 46107 | AC11: 46168 | AD11: 46307 | AE11: Available | AF11: 46336 | AG11: 46378 | AZ11: 46279 | BA11: Holiday | BH11: =IFERROR(K11-W11,"0") -> 0 | BI11: =IFERROR(L11-X11,"0") -> 0 | BJ11: =IFERROR(M11-Y11,"0") -> 0 | BK11: =IFERROR(N11-Z11,"0") -> 0 | BL11: =IFERROR(O11-AA11,"0") -> 0 | BM11: =IFERROR(P11-AB11,"0") -> 0 | BN11: =IFERROR(Q11-AC11,"0") -> 0 | BO11: =IFERROR(R11-AD11,"0") -> 0 | ... BR11: =IFERROR(U11-AG11,"0") -> 0
A12: Brazil_P2 | B12: BRDRNE_P2 | C12: kh.br.sa.bra.18 | D12: Natal | E12: 14335 | F12: Post-drive | J12: 4263 | K12: 46114 | L12: - | M12: - | N12: 46116 | O12: 46117 | P12: 46121 | Q12: 46138 | R12: 46316 | S12: Available | T12: 46341 | U12: 46384 | W12: 46114 | X12: - | Y12: - | Z12: 46116 | AA12: 46117 | AB12: 46121 | AC12: 46138 | AD12: 46316 | AE12: Available | AF12: 46341 | AG12: 46384 | AZ12: 46297 | BA12: Holiday | BH12: =IFERROR(K12-W12,"0") -> 0 | BI12: =IFERROR(L12-X12,"0") -> 0 | BJ12: =IFERROR(M12-Y12,"0") -> 0 | BK12: =IFERROR(N12-Z12,"0") -> 0 | BL12: =IFERROR(O12-AA12,"0") -> 0 | BM12: =IFERROR(P12-AB12,"0") -> 0 | BN12: =IFERROR(Q12-AC12,"0") -> 0 | BO12: =IFERROR(R12-AD12,"0") -> 0 | ... BR12: =IFERROR(U12-AG12,"0") -> 0
A13: Brazil_P2 | B13: BRDRN_P2 | C13: kh.br.sa.bra.13 | D13: Sao Luis | E13: 11777 | F13: Full-drive | J13: 2286 | K13: 46104 | L13: 45663 | M13: 45679 | N13: 46118 | O13: 46120 | P13: 46128 | Q13: 46141 | R13: 46320 | S13: Available | T13: 46344 | U13: 46389 | W13: 46104 | X13: 45663 | Y13: 45679 | Z13: 46118 | AA13: 46120 | AB13: 46128 | AC13: 46141 | AD13: 46320 | AE13: Available | AF13: 46344 | AG13: 46389 | AZ13: 46315 | BA13: Holiday | BH13: =IFERROR(K13-W13,"0") -> 0 | BI13: =IFERROR(L13-X13,"0") -> 0 | BJ13: =IFERROR(M13-Y13,"0") -> 0 | BK13: =IFERROR(N13-Z13,"0") -> 0 | BL13: =IFERROR(O13-AA13,"0") -> 0 | BM13: =IFERROR(P13-AB13,"0") -> 0 | BN13: =IFERROR(Q13-AC13,"0") -> 0 | BO13: =IFERROR(R13-AD13,"0") -> 0 | ... BR13: =IFERROR(U13-AG13,"0") -> 0
A14: Brazil_P2 | B14: BRDRN_P2 | C14: kh.br.sa.bra.14 | D14: Teresina | E14: 8173 | F14: Full-drive | J14: 1748 | K14: 46105 | L14: 45666 | M14: 45687 | N14: 46123 | O14: 46124 | P14: 46127 | Q14: 46136 | R14: 46323 | S14: Available | T14: 46347 | U14: 46392 | W14: 46105 | X14: 45666 | Y14: 45687 | Z14: 46123 | AA14: 46124 | AB14: 46127 | AC14: 46136 | AD14: 46323 | AE14: Available | AF14: 46347 | AG14: 46392 | AZ14: 46335 | BA14: Holiday | BH14: =IFERROR(K14-W14,"0") -> 0 | BI14: =IFERROR(L14-X14,"0") -> 0 | BJ14: =IFERROR(M14-Y14,"0") -> 0 | BK14: =IFERROR(N14-Z14,"0") -> 0 | BL14: =IFERROR(O14-AA14,"0") -> 0 | BM14: =IFERROR(P14-AB14,"0") -> 0 | BN14: =IFERROR(Q14-AC14,"0") -> 0 | BO14: =IFERROR(R14-AD14,"0") -> 0 | ... BR14: =IFERROR(U14-AG14,"0") -> 0
A15: Brazil_P2 | B15: BRDRN_P2 | C15: kh.br.sa.bra.15 | D15: Fortaleza | E15: 15472 | F15: Full-drive | J15: 4370 | K15: 46135 | L15: 45632 | M15: 45656 | N15: 46142 | O15: 46146 | P15: 46147 | Q15: 46168 | R15: 46333 | S15: Available | T15: 46355 | U15: 46400 | W15: 46135 | X15: 45632 | Y15: 45656 | Z15: 46142 | AA15: 46146 | AB15: 46147 | AC15: 46168 | AD15: 46333 | AE15: Available | AF15: 46355 | AG15: 46400 | AZ15: 46381 | BA15: Holiday | BH15: =IFERROR(K15-W15,"0") -> 0 | BI15: =IFERROR(L15-X15,"0") -> 0 | BJ15: =IFERROR(M15-Y15,"0") -> 0 | BK15: =IFERROR(N15-Z15,"0") -> 0 | BL15: =IFERROR(O15-AA15,"0") -> 0 | BM15: =IFERROR(P15-AB15,"0") -> 0 | BN15: =IFERROR(Q15-AC15,"0") -> 0 | BO15: =IFERROR(R15-AD15,"0") -> 0 | ... BR15: =IFERROR(U15-AG15,"0") -> 0
A16: Brazil_P2 | B16: BRDRN_P2 | C16: kh.br.sa.bra.12 | D16: Palmas | E16: 6544 | F16: Full-drive | J16: 869 | K16: 46148 | L16: 45667 | M16: 45688 | N16: 46149 | O16: 46151 | P16: 46155 | Q16: 46172 | R16: 46338 | S16: Available | T16: 46363 | U16: 46408 | W16: 46148 | X16: 45667 | Y16: 45688 | Z16: 46149 | AA16: 46151 | AB16: 46155 | AC16: 46172 | AD16: 46338 | AE16: Available | AF16: 46363 | AG16: 46408 | AZ16: 46388 | BA16: Holiday | BH16: =IFERROR(K16-W16,"0") -> 0 | BI16: =IFERROR(L16-X16,"0") -> 0 | BJ16: =IFERROR(M16-Y16,"0") -> 0 | BK16: =IFERROR(N16-Z16,"0") -> 0 | BL16: =IFERROR(O16-AA16,"0") -> 0 | BM16: =IFERROR(P16-AB16,"0") -> 0 | BN16: =IFERROR(Q16-AC16,"0") -> 0 | BO16: =IFERROR(R16-AD16,"0") -> 0 | ... BR16: =IFERROR(U16-AG16,"0") -> 0
A17: Brazil_P2 | B17: BRDRC_A_P2 | C17: kh.br.sa.bra.10_B | D17: Uberlândia | E17: 24034 | F17: Post-drive | J17: 20596 | K17: 46098 | L17: - | M17: - | N17: 46106 | O17: 46108 | P17: 46108 | Q17: 46140 | R17: 46354 | S17: Available | T17: 46414 | U17: 46446 | W17: 46098 | X17: - | Y17: - | Z17: 46106 | AA17: 46108 | AB17: 46108 | AC17: 46140 | AD17: 46354 | AE17: Available | AF17: 46414 | AG17: 46446 | AZ17: 46401 | BA17: Holiday | BH17: =IFERROR(K17-W17,"0") -> 0 | BI17: =IFERROR(L17-X17,"0") -> 0 | BJ17: =IFERROR(M17-Y17,"0") -> 0 | BK17: =IFERROR(N17-Z17,"0") -> 0 | BL17: =IFERROR(O17-AA17,"0") -> 0 | BM17: =IFERROR(P17-AB17,"0") -> 0 | BN17: =IFERROR(Q17-AC17,"0") -> 0 | BO17: =IFERROR(R17-AD17,"0") -> 0 | ... BR17: =IFERROR(U17-AG17,"0") -> 0
A18: Brazil_P2 | B18: BRDRC_A_P2 | C18: kh.br.sa.bra.10_A | D18: Belo Horizonte | E18: 18327 | F18: Post-drive | J18: 10270 | K18: 46155 | L18: - | M18: - | N18: 46157 | O18: 46160 | P18: 46160 | Q18: 46200 | R18: 46369 | S18: Available | T18: 46426 | U18: 46471 | W18: 46155 | X18: - | Y18: - | Z18: 46157 | AA18: 46160 | AB18: 46160 | AC18: 46200 | AD18: 46369 | AE18: Available | AF18: 46426 | AG18: 46471 | AZ18: 46413 | BA18: Holiday | BH18: =IFERROR(K18-W18,"0") -> 0 | BI18: =IFERROR(L18-X18,"0") -> 0 | BJ18: =IFERROR(M18-Y18,"0") -> 0 | BK18: =IFERROR(N18-Z18,"0") -> 0 | BL18: =IFERROR(O18-AA18,"0") -> 0 | BM18: =IFERROR(P18-AB18,"0") -> 0 | BN18: =IFERROR(Q18-AC18,"0") -> 0 | BO18: =IFERROR(R18-AD18,"0") -> 0 | ... BR18: =IFERROR(U18-AG18,"0") -> 0
A19: Brazil_P2 | B19: BRDRC_A_P2 | C19: kh.br.sa.bra.09_B | D19: Goiânia | E19: 27365 | F19: Full-drive | J19: 10049 | K19: 46201 | L19: 45677 | M19: 45689 | N19: 46229 | O19: 46233 | P19: 46247 | Q19: 46265 | R19: 46383 | S19: Available | T19: 46439 | U19: 46484 | W19: 46201 | X19: 45677 | Y19: 45689 | Z19: 46229 | AA19: 46233 | AB19: 46247 | AC19: 46265 | AD19: 46383 | AE19: Available | AF19: 46439 | AG19: 46484 | AZ19: 46480 | BA19: Holiday | BH19: =IFERROR(K19-W19,"0") -> 0 | BI19: =IFERROR(L19-X19,"0") -> 0 | BJ19: =IFERROR(M19-Y19,"0") -> 0 | BK19: =IFERROR(N19-Z19,"0") -> 0 | BL19: =IFERROR(O19-AA19,"0") -> 0 | BM19: =IFERROR(P19-AB19,"0") -> 0 | BN19: =IFERROR(Q19-AC19,"0") -> 0 | BO19: =IFERROR(R19-AD19,"0") -> 0 | ... BR19: =IFERROR(U19-AG19,"0") -> 0
A20: Brazil_P2 | B20: BRDRC_A_P2 | C20: kh.br.sa.bra.09_A | D20: Brasília | E20: 8952 | F20: Full-drive | J20: 4111 | K20: 46212 | L20: 45654 | M20: 45657 | N20: 46214 | O20: 46220 | P20: 46223 | Q20: 46259 | R20: 46389 | S20: Available | T20: 46449 | U20: 46494 | W20: 46212 | X20: 45654 | Y20: 45657 | Z20: 46214 | AA20: 46220 | AB20: 46223 | AC20: 46259 | AD20: 46389 | AE20: Available | AF20: 46449 | AG20: 46494 | AZ20: 46508 | BA20: Holiday | BH20: =IFERROR(K20-W20,"0") -> 0 | BI20: =IFERROR(L20-X20,"0") -> 0 | BJ20: =IFERROR(M20-Y20,"0") -> 0 | BK20: =IFERROR(N20-Z20,"0") -> 0 | BL20: =IFERROR(O20-AA20,"0") -> 0 | BM20: =IFERROR(P20-AB20,"0") -> 0 | BN20: =IFERROR(Q20-AC20,"0") -> 0 | BO20: =IFERROR(R20-AD20,"0") -> 0 | ... BR20: =IFERROR(U20-AG20,"0") -> 0
A21: Brazil_P2 | B21: BRDRS_A_P2 | C21: kh.br.sa.bra.07_A | D21: Curitiba | E21: 28875 | F21: Post-drive | H21: 649 | I21: 8884 | J21: 14772 | K21: 46312 | L21: - | M21: - | N21: 46313 | O21: 46327 | P21: 46328 | Q21: 46349 | R21: 46404 | S21: Available | T21: 46465 | U21: 46510 | W21: 46312 | X21: - | Y21: - | Z21: 46313 | AA21: 46327 | AB21: 46328 | AC21: 46349 | AD21: 46404 | AE21: Available | AF21: 46465 | AG21: 46510 | AZ21: 46534 | BA21: Holiday | BH21: =IFERROR(K21-W21,"0") -> 0 | BI21: =IFERROR(L21-X21,"0") -> 0 | BJ21: =IFERROR(M21-Y21,"0") -> 0 | BK21: =IFERROR(N21-Z21,"0") -> 0 | BL21: =IFERROR(O21-AA21,"0") -> 0 | BM21: =IFERROR(P21-AB21,"0") -> 0 | BN21: =IFERROR(Q21-AC21,"0") -> 0 | BO21: =IFERROR(R21-AD21,"0") -> 0 | ... BR21: =IFERROR(U21-AG21,"0") -> 0
A22: Brazil_P2 | B22: BRDRS_A_P2 | C22: kh.br.sa.bra.06 | D22: Porto Alegre | E22: 24358 | F22: Full-drive | I22: 8576 | J22: 14356 | K22: 46233 | L22: 45669 | M22: 45688 | N22: 46248 | O22: 46258 | P22: 46305 | Q22: 46323 | R22: 46414 | S22: Available | T22: 46479 | U22: 46519 | W22: 46233 | X22: 45669 | Y22: 45688 | Z22: 46248 | AA22: 46258 | AB22: 46305 | AC22: 46323 | AD22: 46414 | AE22: Available | AF22: 46479 | AG22: 46519 | AZ22: 46540 | BA22: Holiday | BH22: =IFERROR(K22-W22,"0") -> 0 | BI22: =IFERROR(L22-X22,"0") -> 0 | BJ22: =IFERROR(M22-Y22,"0") -> 0 | BK22: =IFERROR(N22-Z22,"0") -> 0 | BL22: =IFERROR(O22-AA22,"0") -> 0 | BM22: =IFERROR(P22-AB22,"0") -> 0 | BN22: =IFERROR(Q22-AC22,"0") -> 0 | BO22: =IFERROR(R22-AD22,"0") -> 0 | ... BR22: =IFERROR(U22-AG22,"0") -> 0
A23: Brazil_P2 | B23: BRDRS_A_P2 | C23: kh.br.sa.bra.05 | D23: Corumba | E23: 12741 | F23: Post-drive | J23: 4124 | K23: 46245 | L23: - | M23: - | N23: 46247 | O23: 46248 | P23: 46275 | Q23: 46285 | R23: 46419 | S23: Available | T23: 46487 | U23: 46524 | W23: 46245 | X23: - | Y23: - | Z23: 46247 | AA23: 46248 | AB23: 46275 | AC23: 46293 | AD23: 46419 | AE23: Available | AF23: 46487 | AG23: 46524 | AZ23: 46614 | BA23: Holiday | BH23: =IFERROR(K23-W23,"0") -> 0 | BI23: =IFERROR(L23-X23,"0") -> 0 | BJ23: =IFERROR(M23-Y23,"0") -> 0 | BK23: =IFERROR(N23-Z23,"0") -> 0 | BL23: =IFERROR(O23-AA23,"0") -> 0 | BM23: =IFERROR(P23-AB23,"0") -> 0 | BN23: =IFERROR(Q23-AC23,"0") -> -8 | BO23: =IFERROR(R23-AD23,"0") -> 0 | ... BR23: =IFERROR(U23-AG23,"0") -> 0
A24: Brazil_P2 | B24: BRDRS_A_P2 | C24: kh.br.sa.bra.07_B | D24: Joinville | E24: 16540 | F24: Full-drive | H24: 1845 | I24: 5490 | J24: 8436 | K24: 46350 | L24: 45689 | M24: 45698 | N24: 46351 | O24: 46372 | P24: 46373 | Q24: 46403 | R24: 46427 | S24: Available | T24: 46497 | U24: 46532 | W24: 46350 | X24: 45689 | Y24: 45698 | Z24: 46351 | AA24: 46372 | AB24: 46373 | AC24: 46403 | AD24: 46427 | AE24: Available | AF24: 46497 | AG24: 46532 | AZ24: 46644 | BA24: Holiday | BH24: =IFERROR(K24-W24,"0") -> 0 | BI24: =IFERROR(L24-X24,"0") -> 0 | BJ24: =IFERROR(M24-Y24,"0") -> 0 | BK24: =IFERROR(N24-Z24,"0") -> 0 | BL24: =IFERROR(O24-AA24,"0") -> 0 | BM24: =IFERROR(P24-AB24,"0") -> 0 | BN24: =IFERROR(Q24-AC24,"0") -> 0 | BO24: =IFERROR(R24-AD24,"0") -> 0 | ... BR24: =IFERROR(U24-AG24,"0") -> 0
A25: Brazil_P2 | B25: BRDRW_P2 | C25: kh.br.sa.bra.04 | D25: Cuiaba | E25: 13464 | F25: Post-drive | I25: 2508 | J25: 6545 | K25: 46253 | L25: - | M25: - | N25: 46259 | O25: 46262 | P25: 46307 | Q25: 46325 | R25: 46434 | S25: Available | T25: 46507 | U25: 46538 | W25: 46253 | X25: - | Y25: - | Z25: 46259 | AA25: 46262 | AB25: 46307 | AC25: 46325 | AD25: 46434 | AE25: Available | AF25: 46507 | AG25: 46538 | AZ25: 46662 | BA25: Holiday | BH25: =IFERROR(K25-W25,"0") -> 0 | BI25: =IFERROR(L25-X25,"0") -> 0 | BJ25: =IFERROR(M25-Y25,"0") -> 0 | BK25: =IFERROR(N25-Z25,"0") -> 0 | BL25: =IFERROR(O25-AA25,"0") -> 0 | BM25: =IFERROR(P25-AB25,"0") -> 0 | BN25: =IFERROR(Q25-AC25,"0") -> 0 | BO25: =IFERROR(R25-AD25,"0") -> 0 | ... BR25: =IFERROR(U25-AG25,"0") -> 0
A26: Brazil_P2 | B26: BRDRW_P2 | C26: kh.br.sa.bra.01 | D26: Porto Velho | E26: 5848 | F26: Zero-drive | J26: 2920 | K26: 46259 | L26: 45602 | M26: 45604 | N26: 46260 | O26: 46263 | P26: 46281 | Q26: 46284 | R26: 46435 | S26: Available | T26: 46512 | U26: 46542 | W26: 46259 | X26: 45602 | Y26: 45604 | Z26: 46260 | AA26: 46263 | AB26: 46280 | AC26: 46295 | AD26: 46435 | AE26: Available | AF26: 46512 | AG26: 46542 | AZ26: 46680 | BA26: Holiday | BH26: =IFERROR(K26-W26,"0") -> 0 | BI26: =IFERROR(L26-X26,"0") -> 0 | BJ26: =IFERROR(M26-Y26,"0") -> 0 | BK26: =IFERROR(N26-Z26,"0") -> 0 | BL26: =IFERROR(O26-AA26,"0") -> 0 | BM26: =IFERROR(P26-AB26,"0") -> 1 | BN26: =IFERROR(Q26-AC26,"0") -> -11 | BO26: =IFERROR(R26-AD26,"0") -> 0 | ... BR26: =IFERROR(U26-AG26,"0") -> 0
A27: Brazil_P2 | B27: BRDRW_P2 | C27: kh.br.sa.bra.03 | D27: Belem | E27: 8948 | F27: Zero-drive | H27: 2408 | I27: 718 | J27: 5554 | K27: 46272 | L27: 45604 | M27: 45614 | N27: 46282 | O27: 46296 | P27: 46300 | Q27: 46321 | R27: 46437 | S27: Available | T27: 46518 | U27: 46544 | W27: 46272 | X27: 45604 | Y27: 45614 | Z27: 46280 | AA27: 46296 | AB27: 46300 | AC27: 46321 | AD27: 46437 | AE27: Available | AF27: 46518 | AG27: 46544 | AZ27: 46700 | BA27: Holiday | BH27: =IFERROR(K27-W27,"0") -> 0 | BI27: =IFERROR(L27-X27,"0") -> 0 | BJ27: =IFERROR(M27-Y27,"0") -> 0 | BK27: =IFERROR(N27-Z27,"0") -> 2 | BL27: =IFERROR(O27-AA27,"0") -> 0 | BM27: =IFERROR(P27-AB27,"0") -> 0 | BN27: =IFERROR(Q27-AC27,"0") -> 0 | BO27: =IFERROR(R27-AD27,"0") -> 0 | ... BR27: =IFERROR(U27-AG27,"0") -> 0
A28: Brazil_P2 | B28: BRDRW_P2 | C28: kh.br.sa.bra.02 | D28: Manaus | E28: 13424 | F28: Post-drive | H28: 226 | I28: 318 | J28: 3840 | K28: 46276 | L28: - | M28: - | N28: 46282 | O28: 46299 | P28: 46302 | Q28: 46326 | R28: 46437 | S28: Available | T28: 46523 | U28: 46546 | W28: 46276 | X28: - | Y28: - | Z28: 46280 | AA28: 46299 | AB28: 46302 | AC28: 46326 | AD28: 46437 | AE28: Available | AF28: 46523 | AG28: 46546 | AZ28: 46746 | BA28: Holiday | BH28: =IFERROR(K28-W28,"0") -> 0 | BI28: =IFERROR(L28-X28,"0") -> 0 | BJ28: =IFERROR(M28-Y28,"0") -> 0 | BK28: =IFERROR(N28-Z28,"0") -> 2 | BL28: =IFERROR(O28-AA28,"0") -> 0 | BM28: =IFERROR(P28-AB28,"0") -> 0 | BN28: =IFERROR(Q28-AC28,"0") -> 0 | BO28: =IFERROR(R28-AD28,"0") -> 0 | ... BR28: =IFERROR(U28-AG28,"0") -> 0
A29: Indonesia | B29: IDDRSM | C29: kh.br.as.idn.01 | D29: Aceh | E29: 7632.6119 | F29: FD | G29: 237 | H29: 676 | I29: 843 | J29: 608 | K29: 46594 | L29: 46579 | M29: 46589 | N29: 46595 | O29: 46609 | P29: 46610 | Q29: 46635 | R29: 46719 | S29: Not Available | T29: 46720 | U29: 46735 | W29: 46594 | X29: 46579 | Y29: 46589 | Z29: 46595 | AA29: 46609 | AB29: 46610 | AC29: 46635 | AD29: 46719 | AE29: Not Available | AF29: 46720 | AG29: 46735 | AZ29: 46753 | BA29: Holiday | BH29: =IFERROR(K29-W29,"0") -> 0 | BI29: =IFERROR(L29-X29,"0") -> 0 | BJ29: =IFERROR(M29-Y29,"0") -> 0 | BK29: =IFERROR(N29-Z29,"0") -> 0 | BL29: =IFERROR(O29-AA29,"0") -> 0 | BM29: =IFERROR(P29-AB29,"0") -> 0 | BN29: =IFERROR(Q29-AC29,"0") -> 0 | BO29: =IFERROR(R29-AD29,"0") -> 0 | ... BR29: =IFERROR(U29-AG29,"0") -> 0
A30: Indonesia | B30: IDDRSM | C30: kh.br.as.idn.05 | D30: Lampung | E30: 11419.856 | F30: FD | G30: 405 | H30: 1155 | I30: 1441 | J30: 1037 | K30: 46627 | L30: 46612 | M30: 46622 | N30: 46628 | O30: 46642 | P30: 46643 | Q30: 46668 | R30: 46739 | S30: Not Available | T30: 46740 | U30: 46762 | W30: 46627 | X30: 46612 | Y30: 46622 | Z30: 46628 | AA30: 46642 | AB30: 46643 | AC30: 46668 | AD30: 46739 | AE30: Not Available | AF30: 46740 | AG30: 46762 | AZ30: 46778 | BA30: Holiday | BH30: =IFERROR(K30-W30,"0") -> 0 | BI30: =IFERROR(L30-X30,"0") -> 0 | BJ30: =IFERROR(M30-Y30,"0") -> 0 | BK30: =IFERROR(N30-Z30,"0") -> 0 | BL30: =IFERROR(O30-AA30,"0") -> 0 | BM30: =IFERROR(P30-AB30,"0") -> 0 | BN30: =IFERROR(Q30-AC30,"0") -> 0 | BO30: =IFERROR(R30-AD30,"0") -> 0 | ... BR30: =IFERROR(U30-AG30,"0") -> 0
A31: Indonesia | B31: IDDRSM | C31: kh.br.as.idn.04 | D31: Sumatra Island South | E31: 21126.636 | F31: FD | G31: 697 | H31: 1985 | I31: 2478 | J31: 1781 | K31: 46639 | L31: 46624 | M31: 46634 | N31: 46640 | O31: 46654 | P31: 46655 | Q31: 46679 | R31: 46754 | S31: Not Available | T31: 46756 | U31: 46777 | W31: 46639 | X31: 46624 | Y31: 46634 | Z31: 46640 | AA31: 46654 | AB31: 46655 | AC31: 46679 | AD31: 46754 | AE31: Not Available | AF31: 46756 | AG31: 46777 | AZ31: 46846 | BA31: Holiday | BH31: =IFERROR(K31-W31,"0") -> 0 | BI31: =IFERROR(L31-X31,"0") -> 0 | BJ31: =IFERROR(M31-Y31,"0") -> 0 | BK31: =IFERROR(N31-Z31,"0") -> 0 | BL31: =IFERROR(O31-AA31,"0") -> 0 | BM31: =IFERROR(P31-AB31,"0") -> 0 | BN31: =IFERROR(Q31-AC31,"0") -> 0 | BO31: =IFERROR(R31-AD31,"0") -> 0 | ... BR31: =IFERROR(U31-AG31,"0") -> 0
A32: Indonesia | B32: IDDRSM | C32: kh.br.as.idn.03 | D32: Sumatra Island Central | E32: 20891.286 | F32: FD | G32: 630 | H32: 1793 | I32: 2239 | J32: 1611 | K32: 46651 | L32: 46636 | M32: 46646 | N32: 46652 | O32: 46666 | P32: 46667 | Q32: 46692 | R32: 46766 | S32: Not Available | T32: 46768 | U32: 46790 | W32: 46651 | X32: 46636 | Y32: 46646 | Z32: 46652 | AA32: 46666 | AB32: 46667 | AC32: 46692 | AD32: 46766 | AE32: Not Available | AF32: 46768 | AG32: 46790 | AZ32: 46874 | BA32: Holiday | BH32: =IFERROR(K32-W32,"0") -> 0 | BI32: =IFERROR(L32-X32,"0") -> 0 | BJ32: =IFERROR(M32-Y32,"0") -> 0 | BK32: =IFERROR(N32-Z32,"0") -> 0 | BL32: =IFERROR(O32-AA32,"0") -> 0 | BM32: =IFERROR(P32-AB32,"0") -> 0 | BN32: =IFERROR(Q32-AC32,"0") -> 0 | BO32: =IFERROR(R32-AD32,"0") -> 0 | ... BR32: =IFERROR(U32-AG32,"0") -> 0
A33: Indonesia | B33: IDDRSM | C33: kh.br.as.idn.02 | D33: Medan | E33: 17053.204 | F33: FD | G33: 666 | H33: 1897 | I33: 2368 | J33: 1704 | K33: 46659 | L33: 46645 | M33: 46654 | N33: 46660 | O33: 46674 | P33: 46675 | Q33: 46699 | R33: 46780 | S33: Not Available | T33: 46781 | U33: 46803 | W33: 46659 | X33: 46645 | Y33: 46654 | Z33: 46660 | AA33: 46674 | AB33: 46675 | AC33: 46699 | AD33: 46780 | AE33: Not Available | AF33: 46781 | AG33: 46803 | AZ33: 46900 | BA33: Holiday | BH33: =IFERROR(K33-W33,"0") -> 0 | BI33: =IFERROR(L33-X33,"0") -> 0 | BJ33: =IFERROR(M33-Y33,"0") -> 0 | BK33: =IFERROR(N33-Z33,"0") -> 0 | BL33: =IFERROR(O33-AA33,"0") -> 0 | BM33: =IFERROR(P33-AB33,"0") -> 0 | BN33: =IFERROR(Q33-AC33,"0") -> 0 | BO33: =IFERROR(R33-AD33,"0") -> 0 | ... BR33: =IFERROR(U33-AG33,"0") -> 0
A34: Indonesia | B34: IDDRKA | C34: kh.br.as.idn.07 | D34: West Kalimantan | E34: 24285.384 | F34: FD | G34: 364 | H34: 1036 | I34: 1293 | J34: 931 | K34: 46663 | L34: 46648 | M34: 46658 | N34: 46664 | O34: 46678 | P34: 46679 | Q34: 46704 | R34: 46794 | S34: Not Available | T34: 46795 | U34: 46817 | W34: 46663 | X34: 46648 | Y34: 46658 | Z34: 46664 | AA34: 46678 | AB34: 46679 | AC34: 46704 | AD34: 46794 | AE34: Not Available | AF34: 46795 | AG34: 46817 | AZ34: 46906 | BA34: Holiday | BH34: =IFERROR(K34-W34,"0") -> 0 | BI34: =IFERROR(L34-X34,"0") -> 0 | BJ34: =IFERROR(M34-Y34,"0") -> 0 | BK34: =IFERROR(N34-Z34,"0") -> 0 | BL34: =IFERROR(O34-AA34,"0") -> 0 | BM34: =IFERROR(P34-AB34,"0") -> 0 | BN34: =IFERROR(Q34-AC34,"0") -> 0 | BO34: =IFERROR(R34-AD34,"0") -> 0 | ... BR34: =IFERROR(U34-AG34,"0") -> 0
A35: Indonesia | B35: IDDRKA | C35: kh.br.as.idn.06 | D35: East Kalimantan | E35: 19072.713 | F35: FD | G35: 384 | H35: 1095 | I35: 1367 | J35: 983 | K35: 46666 | L35: 46651 | M35: 46661 | N35: 46667 | O35: 46681 | P35: 46682 | Q35: 46707 | R35: 46805 | S35: Not Available | T35: 46806 | U35: 46828 | W35: 46666 | X35: 46651 | Y35: 46661 | Z35: 46667 | AA35: 46681 | AB35: 46682 | AC35: 46707 | AD35: 46805 | AE35: Not Available | AF35: 46806 | AG35: 46828 | AZ35: 46980 | BA35: Holiday | BH35: =IFERROR(K35-W35,"0") -> 0 | BI35: =IFERROR(L35-X35,"0") -> 0 | BJ35: =IFERROR(M35-Y35,"0") -> 0 | BK35: =IFERROR(N35-Z35,"0") -> 0 | BL35: =IFERROR(O35-AA35,"0") -> 0 | BM35: =IFERROR(P35-AB35,"0") -> 0 | BN35: =IFERROR(Q35-AC35,"0") -> 0 | BO35: =IFERROR(R35-AD35,"0") -> 0 | ... BR35: =IFERROR(U35-AG35,"0") -> 0
A36: Indonesia | B36: IDDRJW | C36: kh.br.as.idn.09 | D36: Jakarta | E36: 3670.6587 | F36: FD | G36: 475 | H36: 1354 | I36: 1690 | J36: 1217 | K36: 46674 | L36: 46659 | M36: 46669 | N36: 46675 | O36: 46689 | P36: 46690 | Q36: 46715 | R36: 46815 | S36: Not Available | T36: 46816 | U36: 46838 | W36: 46674 | X36: 46659 | Y36: 46669 | Z36: 46675 | AA36: 46689 | AB36: 46690 | AC36: 46715 | AD36: 46815 | AE36: Not Available | AF36: 46816 | AG36: 46838 | AZ36: 47028 | BA36: Holiday | BH36: =IFERROR(K36-W36,"0") -> 0 | BI36: =IFERROR(L36-X36,"0") -> 0 | BJ36: =IFERROR(M36-Y36,"0") -> 0 | BK36: =IFERROR(N36-Z36,"0") -> 0 | BL36: =IFERROR(O36-AA36,"0") -> 0 | BM36: =IFERROR(P36-AB36,"0") -> 0 | BN36: =IFERROR(Q36-AC36,"0") -> 0 | BO36: =IFERROR(R36-AD36,"0") -> 0 | ... BR36: =IFERROR(U36-AG36,"0") -> 0
A37: Indonesia | B37: IDDRJW | C37: kh.br.as.idn.08 | D37: Banten | E37: 7393.3955 | F37: FD | G37: 536 | H37: 1526 | I37: 1904 | J37: 1373 | K37: 46684 | L37: 46669 | M37: 46679 | N37: 46685 | O37: 46699 | P37: 46701 | Q37: 46725 | R37: 46835 | S37: Not Available | T37: 46836 | U37: 46858 | W37: 46684 | X37: 46669 | Y37: 46679 | Z37: 46685 | AA37: 46699 | AB37: 46701 | AC37: 46725 | AD37: 46835 | AE37: Not Available | AF37: 46836 | AG37: 46858 | AZ37: 47046 | BA37: Holiday | BH37: =IFERROR(K37-W37,"0") -> 0 | BI37: =IFERROR(L37-X37,"0") -> 0 | BJ37: =IFERROR(M37-Y37,"0") -> 0 | BK37: =IFERROR(N37-Z37,"0") -> 0 | BL37: =IFERROR(O37-AA37,"0") -> 0 | BM37: =IFERROR(P37-AB37,"0") -> 0 | BN37: =IFERROR(Q37-AC37,"0") -> 0 | BO37: =IFERROR(R37-AD37,"0") -> 0 | ... BR37: =IFERROR(U37-AG37,"0") -> 0
A38: Indonesia | B38: IDDRJW | C38: kh.br.as.idn.10_A | D38: West Java A | E38: 11005.77 | F38: FD | G38: 777 | H38: 2212 | I38: 2760 | J38: 1988 | K38: 46703 | L38: 46688 | M38: 46698 | N38: 46704 | O38: 46718 | P38: 46719 | Q38: 46744 | R38: 46851 | S38: Not Available | T38: 46852 | U38: 46874 | W38: 46703 | X38: 46688 | Y38: 46698 | Z38: 46704 | AA38: 46718 | AB38: 46719 | AC38: 46744 | AD38: 46851 | AE38: Not Available | AF38: 46852 | AG38: 46874 | AZ38: 47066 | BA38: Holiday | BH38: =IFERROR(K38-W38,"0") -> 0 | BI38: =IFERROR(L38-X38,"0") -> 0 | BJ38: =IFERROR(M38-Y38,"0") -> 0 | BK38: =IFERROR(N38-Z38,"0") -> 0 | BL38: =IFERROR(O38-AA38,"0") -> 0 | BM38: =IFERROR(P38-AB38,"0") -> 0 | BN38: =IFERROR(Q38-AC38,"0") -> 0 | BO38: =IFERROR(R38-AD38,"0") -> 0 | ... BR38: =IFERROR(U38-AG38,"0") -> 0
A39: Indonesia | B39: IDDRJW | C39: kh.br.as.idn.12_C | D39: East Java C | E39: 13706.379 | F39: FD | G39: 632 | H39: 1799 | I39: 2245 | J39: 1616 | K39: 46720 | L39: 46705 | M39: 46715 | N39: 46721 | O39: 46735 | P39: 46736 | Q39: 46761 | R39: 46867 | S39: Not Available | T39: 46868 | U39: 46890 | W39: 46720 | X39: 46705 | Y39: 46715 | Z39: 46721 | AA39: 46735 | AB39: 46736 | AC39: 46761 | AD39: 46867 | AE39: Not Available | AF39: 46868 | AG39: 46890 | AZ39: 47112 | BA39: Holiday | BH39: =IFERROR(K39-W39,"0") -> 0 | BI39: =IFERROR(L39-X39,"0") -> 0 | BJ39: =IFERROR(M39-Y39,"0") -> 0 | BK39: =IFERROR(N39-Z39,"0") -> 0 | BL39: =IFERROR(O39-AA39,"0") -> 0 | BM39: =IFERROR(P39-AB39,"0") -> 0 | BN39: =IFERROR(Q39-AC39,"0") -> 0 | BO39: =IFERROR(R39-AD39,"0") -> 0 | ... BR39: =IFERROR(U39-AG39,"0") -> 0
A40: Indonesia | B40: IDDRJW | C40: kh.br.as.idn.11_C | D40: Yogyakarta | E40: 13092.842 | F40: FD | G40: 483 | H40: 1375 | I40: 1715 | J40: 1234 | K40: 46738 | L40: 46723 | M40: 46733 | N40: 46739 | O40: 46754 | P40: 46755 | Q40: 46779 | R40: 46880 | S40: Not Available | T40: 46882 | U40: 46903 | W40: 46738 | X40: 46723 | Y40: 46733 | Z40: 46739 | AA40: 46754 | AB40: 46755 | AC40: 46779 | AD40: 46880 | AE40: Not Available | AF40: 46882 | AG40: 46903 | BH40: =IFERROR(K40-W40,"0") -> 0 | BI40: =IFERROR(L40-X40,"0") -> 0 | BJ40: =IFERROR(M40-Y40,"0") -> 0 | BK40: =IFERROR(N40-Z40,"0") -> 0 | BL40: =IFERROR(O40-AA40,"0") -> 0 | BM40: =IFERROR(P40-AB40,"0") -> 0 | BN40: =IFERROR(Q40-AC40,"0") -> 0 | BO40: =IFERROR(R40-AD40,"0") -> 0 | ... BR40: =IFERROR(U40-AG40,"0") -> 0
...

Sheet Planner Sequence
A1: Market | B1: Deployment Region | C1: BR Name | D1: BR ID | E1: Planner BR Sequence | H1: Deployment Region | I1: Planner DR Sequence
A2: Brazil | B2: BRDRSP | C2: São Paulo | D2: kh.br.sa.bra.08_A | E2: 1 | H2: BRDRSP | I2: 1
A3: Brazil | B3: BRDRSP | C3: Campinas | D3: kh.br.sa.bra.08_C | E3: 2 | H3: BRDRRIO | I3: 2
A4: Brazil | B4: BRDRSP | C4: Ribeirão Preto | D4: kh.br.sa.bra.08_D | E4: 3 | H4: BRDRNE | I4: 3
A5: Brazil | B5: BRDRSP | C5: São José dos Campos | D5: kh.br.sa.bra.08_B | E5: 4 | H5: BRDRN | I5: 4
A6: Brazil | B6: BRDRRIO | C6: Rio de Janeiro | D6: kh.br.sa.bra.11_A | E6: 5 | H6: BRDRC_A | I6: 5
A7: Brazil | B7: BRDRRIO | C7: Campos dos Goytacazes | D7: kh.br.sa.bra.11_B | E7: 6 | H7: BRDRS_A | I7: 6
A8: Brazil | B8: BRDRRIO | C8: Vitória | D8: kh.br.sa.bra.11_C | E8: 7 | H8: BRDRW | I8: 7
A9: Brazil | B9: BRDRNE | C9: Salvador | D9: kh.br.sa.bra.16 | E9: 8
A10: Brazil | B10: BRDRNE | C10: Recife | D10: kh.br.sa.bra.17 | E10: 9
A11: Brazil | B11: BRDRNE | C11: Natal | D11: kh.br.sa.bra.18 | E11: 10
A12: Brazil | B12: BRDRN | C12: Sao Luis | D12: kh.br.sa.bra.13 | E12: 11
A13: Brazil | B13: BRDRN | C13: Teresina | D13: kh.br.sa.bra.14 | E13: 12
A14: Brazil | B14: BRDRN | C14: Fortaleza | D14: kh.br.sa.bra.15 | E14: 13
A15: Brazil | B15: BRDRN | C15: Palmas | D15: kh.br.sa.bra.12 | E15: 14
A16: Brazil | B16: BRDRC_A | C16: Uberlândia | D16: kh.br.sa.bra.10_B | E16: 15
A17: Brazil | B17: BRDRC_A | C17: Belo Horizonte | D17: kh.br.sa.bra.10_A | E17: 16
A18: Brazil | B18: BRDRC_A | C18: Goiânia | D18: kh.br.sa.bra.09_B | E18: 17
A19: Brazil | B19: BRDRC_A | C19: Brasília | D19: kh.br.sa.bra.09_A | E19: 18
A20: Brazil | B20: BRDRS_A | C20: Curitiba | D20: kh.br.sa.bra.07_A | E20: 19
... A27: Brazil | B27: BRDRW | C27: Manaus | D27: kh.br.sa.bra.02 | E27: 26

Sheet Country End date
B1: Country | C1: Status | D1: Country End Dates & Variance | P1: Addressing Start & End date
D2: Naming | G2: DC2 | J2: Addressing | N2: Country | O2: Status | P2: LTP 9/21 | AC2: Country | AD2: Status | AE2: LTP 9/14 | AL2: Country | AM2: Status | AN2: MPRA End Dates | AQ2: Remarks | AS2: Markets | AT2: Addressing Initiation Date
D3: =P2 -> LTP 9/21 | E3: =AE2 -> LTP 9/14 | F3: Naming QA Variance | G3: =D3 -> LTP 9/21 | H3: =E3 -> LTP 9/14 | I3: DC2 Variance | J3: =G3 -> LTP 9/21 | K3: =H3 -> LTP 9/14 | L3: MPRA Stage End date Variance | P3: Naming QA | Q3: Naming QA Variance | R3: HLA Stage Start date | S3: HLA Stage Start date Variance | T3: HLA Stage End date | U3: HLA Stage End date Variance | V3: ADC Stage End date | W3: ADC Stage End date Variance | X3: DC2 | Y3: DC2 Variance | Z3: MPRA Stage End date | AA3: MPRA Stage End date Variance | AE3: Naming QA | AF3: HLA Phase start date | AG3: HLA Phase end date | AH3: ADC Phase end date | AI3: DC2 | AJ3: MPRA Phase end date | AN3: =J3 -> LTP 9/21 | AO3: =K3 -> LTP 9/14 | AP3: Variance
B4: Brazil_P2 | C4: WIP | D4: =P4 -> 46350 | E4: =AE4 -> 46350 | F4: =D4-E4 -> 0 | G4: =X4 -> 46437 | H4: =AI4 -> 46437 | I4: =G4-H4 -> 0 | J4: =Z4 -> 46546 | K4: =AJ4 -> 46546 | L4: =J4-K4 -> 0 | N4: Brazil_P2 | O4: WIP | P4: {=MAX(IF('LTP 21-Sep-26'!A:A='Country End date'!N4,'LTP 21-Sep-26'!K:K))} -> 46350 | Q4: =IFERROR((P4-AE4),"-") -> 0 | R4: {=MIN(IF('LTP 21-Sep-26'!A:A='Country End date'!N4,'LTP 21-Sep-26'!N:N))} -> 46028 | S4: =IFERROR((R4-AF4),"-") -> 0 | T4: {=MAX(IF('LTP 21-Sep-26'!A:A='Country End date'!N4,'LTP 21-Sep-26'!O:O))} -> 46372 | U4: =IFERROR((T4-AG4),"-") -> 0 | V4: {=MAX(IF('LTP 21-Sep-26'!A:A='Country End date'!N4,'LTP 21-Sep-26'!Q:Q))} -> 46403 | W4: =IFERROR((V4-AH4),"-") -> 0 | X4: {=MAX(IF('LTP 21-Sep-26'!A:A='Country End date'!N4,'LTP 21-Sep-26'!R:R))} -> 46437 | Y4: =IFERROR((X4-AI4),"-") -> 0 | Z4: {=MAX(IF('LTP 21-Sep-26'!A:A='Country End date'!N4,'LTP 21-Sep-26'!U:U))} -> 46546 | AA4: =IFERROR((Z4-AJ4),"-") -> 0 | AC4: Brazil_P2 | AD4: WIP | AE4: 46350 | AF4: 46028 | AG4: 46372 | AH4: 46403 | AI4: 46437 | AJ4: 46546 | AL4: Brazil_P2 | AM4: WIP | AN4: =J4 -> 46546 | AO4: =K4 -> 46546 | AP4: =AN4-AO4 -> 0 | AQ4: - | AS4: Brazil_P2 | AT4: =R4 -> 46028
B5: Indonesia | C5: YTS | D5: =P5 -> 46876 | E5: =AE5 -> 46876 | F5: =D5-E5 -> 0 | G5: =X5 -> 46975 | H5: =AI5 -> 46975 | I5: =G5-H5 -> 0 | J5: =Z5 -> 46998 | K5: =AJ5 -> 46998 | L5: =J5-K5 -> 0 | N5: Indonesia | O5: YTS | P5: {=MAX(IF('LTP 21-Sep-26'!A:A='Country End date'!N5,'LTP 21-Sep-26'!K:K))} -> 46876 | Q5: =IFERROR((P5-AE5),"-") -> 0 | R5: {=MIN(IF('LTP 21-Sep-26'!A:A='Country End date'!N5,'LTP 21-Sep-26'!N:N))} -> 46595 | S5: =IFERROR((R5-AF5),"-") -> 0 | T5: {=MAX(IF('LTP 21-Sep-26'!A:A='Country End date'!N5,'LTP 21-Sep-26'!O:O))} -> 46891 | U5: =IFERROR((T5-AG5),"-") -> 0 | V5: {=MAX(IF('LTP 21-Sep-26'!A:A='Country End date'!N5,'LTP 21-Sep-26'!Q:Q))} -> 46917 | W5: =IFERROR((V5-AH5),"-") -> 0 | X5: {=MAX(IF('LTP 21-Sep-26'!A:A='Country End date'!N5,'LTP 21-Sep-26'!R:R))} -> 46975 | Y5: =IFERROR((X5-AI5),"-") -> 0 | Z5: {=MAX(IF('LTP 21-Sep-26'!A:A='Country End date'!N5,'LTP 21-Sep-26'!U:U))} -> 46998 | AA5: =IFERROR((Z5-AJ5),"-") -> 0 | AC5: Indonesia | AD5: YTS | AE5: 46876 | AF5: 46595 | AG5: 46891 | AH5: 46917 | AI5: 46975 | AJ5: 46998 | AL5: Indonesia | AM5: YTS | AN5: =J5 -> 46998 | AO5: =K5 -> 46998 | AP5: =AN5-AO5 -> 0 | AQ5: - | AS5: Indonesia | AT5: =R5 -> 46595
B6: Philippines | C6: YTS | D6: =P6 -> 46978 | E6: =AE6 -> 46978 | F6: =D6-E6 -> 0 | G6: =X6 -> 47073 | H6: =AI6 -> 47073 | I6: =G6-H6 -> 0 | J6: =Z6 -> 47094 | K6: =AJ6 -> 47094 | L6: =J6-K6 -> 0 | N6: Philippines | O6: YTS | P6: {=MAX(IF('LTP 21-Sep-26'!A:A='Country End date'!N6,'LTP 21-Sep-26'!K:K))} -> 46978 | Q6: =IFERROR((P6-AE6),"-") -> 0 | R6: {=MIN(IF('LTP 21-Sep-26'!A:A='Country End date'!N6,'LTP 21-Sep-26'!N:N))} -> 46839 | S6: =IFERROR((R6-AF6),"-") -> 0 | T6: {=MAX(IF('LTP 21-Sep-26'!A:A='Country End date'!N6,'LTP 21-Sep-26'!O:O))} -> 46987 | U6: =IFERROR((T6-AG6),"-") -> 0 | V6: {=MAX(IF('LTP 21-Sep-26'!A:A='Country End date'!N6,'LTP 21-Sep-26'!Q:Q))} -> 47013 | W6: =IFERROR((V6-AH6),"-") -> 0 | X6: {=MAX(IF('LTP 21-Sep-26'!A:A='Country End date'!N6,'LTP 21-Sep-26'!R:R))} -> 47073 | Y6: =IFERROR((X6-AI6),"-") -> 0 | Z6: {=MAX(IF('LTP 21-Sep-26'!A:A='Country End date'!N6,'LTP 21-Sep-26'!U:U))} -> 47094 | AA6: =IFERROR((Z6-AJ6),"-") -> 0 | AC6: Philippines | AD6: YTS | AE6: 46978 | AF6: 46839 | AG6: 46987 | AH6: 47013 | AI6: 47073 | AJ6: 47094 | AL6: Philippines | AM6: YTS | AN6: =J6 -> 47094 | AO6: =K6 -> 47094 | AP6: =AN6-AO6 -> 0 | AQ6: - | AS6: Philippines | AT6: =R6 -> 46839

Sheet Variance in LTP vs LTP
G1: Naming QA Acceptance | J1: DC2 | M1: Addressing Submission | S1: Only Ranges1 & Ranges2 worked in ADC Stage | T1: Full Drive BRs | U1: Completed
A2: Country | B2: DR | C2: Build Region ID | D2: Build Region Name | E2: Phase | F2: KMS | G2: LTP 9/14 | H2: LTP 9/21 | I2: Variance | J2: =G2 -> LTP 9/14 | K2: =H2 -> LTP 9/21 | L2: Variance | M2: =J2 -> LTP 9/14 | N2: =K2 -> LTP 9/21 | O2: Variance | P2: Remarks | S2: Ranges1, Ranges2 & Access Points worked in ADC Stage | T2: Planned/Yet to start | U2: In Progress
A3: Brazil_P2 | B3: BRDRSP_P2 | C3: kh.br.sa.bra.08_A | D3: São Paulo | E3: Phase2 | F3: 34714 | G3: 46022 | H3: 46022 | I3: =IFERROR((H3-G3),"-") -> 0 | J3: 46193 | K3: 46193 | L3: =IFERROR((K3-J3),"-") -> 0 | M3: 46288 | N3: 46288 | O3: =IFERROR((N3-M3),"-") -> 0 | P3: -
A4: Brazil_P2 | B4: BRDRSP_P2 | C4: kh.br.sa.bra.08_C | D4: Campinas | E4: Phase2 | F4: 23453 | G4: 46029 | H4: 46029 | I4: =IFERROR((H4-G4),"-") -> 0 | J4: 46243 | K4: 46243 | L4: =IFERROR((K4-J4),"-") -> 0 | M4: 46320 | N4: 46320 | O4: =IFERROR((N4-M4),"-") -> 0 | P4: -
A5: Brazil_P2 | B5: BRDRSP_P2 | C5: kh.br.sa.bra.08_D | D5: Ribeirão Preto | E5: Phase2 | F5: 23151 | G5: 46041 | H5: 46041 | I5: =IFERROR((H5-G5),"-") -> 0 | J5: 46271 | K5: 46271 | L5: =IFERROR((K5-J5),"-") -> 0 | M5: 46348 | N5: 46348 | O5: =IFERROR((N5-M5),"-") -> 0 | P5: -
A6: Brazil_P2 | B6: BRDRSP_P2 | C6: kh.br.sa.bra.08_B | D6: São José dos Campos | E6: Phase2 | F6: 26018 | G6: 46049 | H6: 46049 | I6: =IFERROR((H6-G6),"-") -> 0 | J6: 46283 | K6: 46283 | L6: =IFERROR((K6-J6),"-") -> 0 | M6: 46353 | N6: 46353 | O6: =IFERROR((N6-M6),"-") -> 0 | P6: -
A7: Brazil_P2 | B7: BRDRRIO_P2 | C7: kh.br.sa.bra.11_A | D7: Rio de Janeiro | E7: Phase2 | F7: 14299 | G7: 46051 | H7: 46051 | I7: =IFERROR((H7-G7),"-") -> 0 | J7: 46210 | K7: 46210 | L7: =IFERROR((K7-J7),"-") -> 0 | M7: 46293 | N7: 46293 | O7: =IFERROR((N7-M7),"-") -> 0 | P7: -
A8: Brazil_P2 | B8: BRDRRIO_P2 | C8: kh.br.sa.bra.11_B | D8: Campos dos Goytacazes | E8: Phase2 | F8: 18163 | G8: 46053 | H8: 46053 | I8: =IFERROR((H8-G8),"-") -> 0 | J8: 46215 | K8: 46215 | L8: =IFERROR((K8-J8),"-") -> 0 | M8: 46307 | N8: 46307 | O8: =IFERROR((N8-M8),"-") -> 0 | P8: -
A9: Brazil_P2 | B9: BRDRRIO_P2 | C9: kh.br.sa.bra.11_C | D9: Vitória | E9: Phase2 | F9: 7469 | G9: 46059 | H9: 46059 | I9: =IFERROR((H9-G9),"-") -> 0 | J9: 46224 | K9: 46224 | L9: =IFERROR((K9-J9),"-") -> 0 | M9: 46301 | N9: 46301 | O9: =IFERROR((N9-M9),"-") -> 0 | P9: -
A10: Brazil_P2 | B10: BRDRNE_P2 | C10: kh.br.sa.bra.16 | D10: Salvador | E10: Phase2 | F10: 23933 | G10: 46075 | H10: 46075 | I10: =IFERROR((H10-G10),"-") -> 0 | J10: 46299 | K10: 46299 | L10: =IFERROR((K10-J10),"-") -> 0 | M10: 46369 | N10: 46369 | O10: =IFERROR((N10-M10),"-") -> 0 | P10: -
A11: Brazil_P2 | B11: BRDRNE_P2 | C11: kh.br.sa.bra.17 | D11: Recife | E11: Phase2 | F11: 22668 | G11: 46091 | H11: 46091 | I11: =IFERROR((H11-G11),"-") -> 0 | J11: 46307 | K11: 46307 | L11: =IFERROR((K11-J11),"-") -> 0 | M11: 46378 | N11: 46378 | O11: =IFERROR((N11-M11),"-") -> 0 | P11: -
A12: Brazil_P2 | B12: BRDRNE_P2 | C12: kh.br.sa.bra.18 | D12: Natal | E12: Phase2 | F12: 14335 | G12: 46114 | H12: 46114 | I12: =IFERROR((H12-G12),"-") -> 0 | J12: 46316 | K12: 46316 | L12: =IFERROR((K12-J12),"-") -> 0 | M12: 46384 | N12: 46384 | O12: =IFERROR((N12-M12),"-") -> 0 | P12: -
A13: Brazil_P2 | B13: BRDRN_P2 | C13: kh.br.sa.bra.13 | D13: Sao Luis | E13: Phase2 | F13: 11777 | G13: 46104 | H13: 46104 | I13: =IFERROR((H13-G13),"-") -> 0 | J13: 46320 | K13: 46320 | L13: =IFERROR((K13-J13),"-") -> 0 | M13: 46389 | N13: 46389 | O13: =IFERROR((N13-M13),"-") -> 0 | P13: -
A14: Brazil_P2 | B14: BRDRN_P2 | C14: kh.br.sa.bra.14 | D14: Teresina | E14: Phase2 | F14: 8173 | G14: 46105 | H14: 46105 | I14: =IFERROR((H14-G14),"-") -> 0 | J14: 46323 | K14: 46323 | L14: =IFERROR((K14-J14),"-") -> 0 | M14: 46392 | N14: 46392 | O14: =IFERROR((N14-M14),"-") -> 0 | P14: -
... A72: Philippines | B72: PHDR3 | C72: kh.br.as.phl.12 | D72: Zamboanga Peninsula | E72: FD | F72: 5603.0375 | G72: 46978 | H72: 46978 | I72: =IFERROR((H72-G72),"-") -> 0 | J72: 47073 | K72: 47073 | L72: =IFERROR((K72-J72),"-") -> 0 | M72: 47094 | N72: 47094 | O72: =IFERROR((N72-M72),"-") -> 0 | P72: Tentative Philippines completion time (7-Dec-28)

Sheet Demand vs Supply
B2: LTP 21-Sep-2026 :: Demand Vs Supply
B3: Month | C3: Working days | D3: Total HC | E3: Daily Login HC | F3: Shrinkage | G3: Attrition | H3: Total Available Capacity | I3: Inventory from Upstream (Naming QA) | J3: Inventory from Upstream (DC2) | K3: Inventory from Product Improvement | L3: Net Inventory coming in current month | M3: Unused Inventory | N3: Remarks
B4: Sep'26 | C4: 8 | D4: =(221-20-25-40-40) -> 96 | E4: =ROUND(D4*5/7,0) -> 69 | F4: 0.9 | G4: 0.985 | H4: =(D4*C4*F4) -> 691.2 | I4: 1967.2 | J4: 7263.4667 | K4: 0 | L4: =(I4+J4+K4) -> 9230.6667 | M4: =IF(L4>0,(L4-H4)) -> 8539.4667 | N4: 20 HC movement extended for Additional Finishing Task & 40 HC for moved temporarily 25 HC moved (Jul'26 to Sep'26) to QA temporarily 40 HC for Highway Service Road task
B5: Oct'26 | C5: 20 | D5: =(221*G5) -> 217.685 | E5: =ROUND(D5*5/7,0) -> 155 | F5: 0.9 | G5: 0.985 | H5: =(D5*C5*F5) -> 3918.33 | I5: 1271.0667 | J5: 3627.7333 | K5: 0 | L5: =(I5+J5+K5) -> 4898.8 | M5: =IF(M4>0,(M4+L5-H5),(L5-H5)) -> 9519.9367 | N5: 20+40 HC move back from Additional Finishing Task 25 HC move back from QA 40 HC move back from Highway Service Road task
B6: Nov'26 | C6: 20 | D6: =(D5*G6) -> 214.41972 | E6: =ROUND(D6*5/7,0) -> 153 | F6: 0.9 | G6: 0.985 | H6: =(D6*C6*F6) -> 3859.5551 | I6: 978 | J6: 3444.6667 | K6: 0 | L6: =(I6+J6+K6) -> 4422.6667 | M6: =IF(M5>0,(M5+L6-H6),(L6-H6)) -> 10083.048 | N6: -
B7: Dec'26 | C7: 22 | D7: =(D6*G7) -> 211.20343 | E7: =ROUND(D7*5/7,0) -> 151 | F7: 0.9 | G7: 0.985 | H7: =(D7*C7*F7) -> 4181.8279 | I7: 0 | J7: 2709.2 | K7: 0 | L7: =(I7+J7+K7) -> 2709.2 | M7: =IF(M6>0,(M6+L7-H7),(L7-H7)) -> 8610.4204 | N7: -
B8: Jan'27 | C8: 18 | D8: =(D7*G8) -> 208.03538 | E8: =ROUND(D8*5/7,0) -> 149 | F8: 0.9 | G8: 0.985 | H8: =(D8*C8*F8) -> 3370.1731 | I8: 0 | J8: 4431.8667 | K8: 0 | L8: =(I8+J8+K8) -> 4431.8667 | M8: =IF(M7>0,(M7+L8-H8),(L8-H8)) -> 9672.1139 | N8: -
B9: Feb'27 | C9: 20 | D9: =(D8*G9) -> 204.91485 | E9: =ROUND(D9*5/7,0) -> 146 | F9: 0.9 | G9: 0.985 | H9: =(D9*C9*F9) -> 3688.4672 | I9: 0 | J9: 4189.2 | K9: 0 | L9: =(I9+J9+K9) -> 4189.2 | M9: =IF(M8>0,(M8+L9-H9),(L9-H9)) -> 10172.847 | N9: -
B10: Mar'27 | C10: 22 | D10: =(D9*G10) -> 201.84112 | E10: =ROUND(D10*5/7,0) -> 144 | F10: 0.9 | G10: 0.985 | H10: =(D10*C10*F10) -> 3996.4543 | I10: 0 | J10: 0 | K10: 0 | L10: =(I10+J10+K10) -> 0 | M10: =IF(M9>0,(M9+L10-H10),(L10-H10)) -> 6176.3924 | N10: -
B11: Apr'27 | C11: 19 | D11: =(D10*G11)-15 -> 183.81351 | E11: =ROUND(D11*5/7,0) -> 131 | F11: 0.9 | G11: 0.985 | H11: =(D11*C11*F11) -> 3143.211 | I11: 0 | J11: 0 | K11: 0 | L11: =(I11+J11+K11) -> 0 | M11: =IF(M10>0,(M10+L11-H11),(L11-H11)) -> 3033.1814 | N11: FunT HC (15) moved to complete IDN FunT
B12: May'27 | C12: 22 | D12: =(D11*G12)+15 -> 196.0563 | E12: =ROUND(D12*5/7,0) -> 140 | F12: 0.9 | G12: 0.985 | H12: =(D12*C12*F12) -> 3881.9148 | I12: 0 | J12: 0 | K12: 0 | L12: =(I12+J12+K12) -> 0 | M12: =IF(M11>0,(M11+L12-H12),(L12-H12)) -> -848.73339 | N12: FunT HC (15) moved back to Production
B13: Jun'27 | C13: 21 | D13: =(D12*G13) -> 193.11546 | E13: =ROUND(D13*5/7,0) -> 138 | F13: 0.9 | G13: 0.985 | H13: =(D13*C13*F13) -> 3649.8822 | I13: 0 | J13: 0 | K13: 0 | L13: =(I13+J13+K13) -> 0 | M13: =IF(M12>0,(M12+L13-H13),(L13-H13)) -> -3649.8822 | N13: Tentative Brazil Phase2 completion time (8-Jun-27)
B14: Jul'27 | C14: 22 | D14: =(D13*G14) -> 190.21873 | E14: =ROUND(D14*5/7,0) -> 136 | F14: 0.9 | G14: 0.985 | H14: =(D14*C14*F14) -> 3766.3308 | I14: 202.53333 | J14: 0 | K14: 31.6 | L14: =(I14+J14+K14) -> 234.13333 | M14: =IF(M13>0,(M13+L14-H14),(L14-H14)) -> -3532.1975 | N14: -
B15: Aug'27 | C15: 22 | D15: =(D14*G15) -> 187.36545 | E15: =ROUND(D15*5/7,0) -> 134 | F15: 0.9 | G15: 0.985 | H15: =(D15*C15*F15) -> 3709.8359 | I15: 346.13333 | J15: 0 | K15: 54 | L15: =(I15+J15+K15) -> 400.13333 | M15: =IF(M14>0,(M14+L15-H15),(L15-H15)) -> -3309.7025 | N15: -
B16: Sep'27 | C16: 21 | D16: =(D15*G16) -> 184.55497 | E16: =ROUND(D16*5/7,0) -> 132 | F16: 0.9 | G16: 0.985 | H16: =(D16*C16*F16) -> 3488.0889 | I16: 1701.3333 | J16: 0 | K16: 265.73333 | L16: =(I16+J16+K16) -> 1967.0667 | M16: =IF(M15>0,(M15+L16-H16),(L16-H16)) -> -1521.0222 | N16: -
B17: Oct'27 | C17: 20 | D17: =(D16*G17) -> 181.78664 | E17: =ROUND(D17*5/7,0) -> 130 | F17: 0.9 | G17: 0.985 | H17: =(D17*C17*F17) -> 3272.1595 | I17: 1502 | J17: 0 | K17: 234.53333 | L17: =(I17+J17+K17) -> 1736.5333 | M17: =IF(M16>0,(M16+L17-H17),(L17-H17)) -> -1535.6262 | N17: -
B18: Nov'27 | C18: 21 | D18: =(D17*G18) -> 179.05984 | E18: =ROUND(D18*5/7,0) -> 128 | F18: 0.9 | G18: 0.985 | H18: =(D18*C18*F18) -> 3384.231 | I18: 1202.1333 | J18: 81.066667 | K18: 187.86667 | L18: =(I18+J18+K18) -> 1471.0667 | M18: =IF(M17>0,(M17+L18-H18),(L18-H18)) -> -1913.1643 | N18: -
B19: Dec'27 | C19: 23 | D19: =(D18*G19)-15 -> 161.37394 | E19: =ROUND(D19*5/7,0) -> 115 | F19: 0.9 | G19: 0.985 | H19: =(D19*C19*F19) -> 3340.4406 | I19: 412 | J19: 138.26667 | K19: 64.4 | L19: =(I19+J19+K19) -> 614.66667 | M19: =IF(M18>0,(M18+L19-H19),(L19-H19)) -> -2725.774 | N19: FunT HC (15) moved to complete PHL FunT
B20: Jan'28 | C20: 19 | D20: =(D19*G20)+15 -> 173.95333 | E20: =ROUND(D20*5/7,0) -> 124 | F20: 0.9 | G20: 0.985 | H20: =(D20*C20*F20) -> 2974.602 | I20: 968.26667 | J20: 679.46667 | K20: 151.2 | L20: =(I20+J20+K20) -> 1798.9333 | M20: =IF(M19>0,(M19+L20-H20),(L20-H20)) -> -1175.6687 | N20: FunT HC (15) moved back to Production
B21: Feb'28 | C21: 21 | D21: =(D20*G21) -> 171.34403 | E21: =ROUND(D21*5/7,0) -> 122 | F21: 0.9 | G21: 0.985 | H21: =(D21*C21*F21) -> 3238.4023 | I21: 1024.6667 | J21: 255.2 | K21: 160 | L21: =(I21+J21+K21) -> 1439.8667 | M21: =IF(M20>0,(M20+L21-H21),(L21-H21)) -> -1798.5356 | N21: -
B22: Mar'28 | C22: 23 | D22: =(D21*G22) -> 168.77387 | E22: =ROUND(D22*5/7,0) -> 121 | F22: 0.9 | G22: 0.985 | H22: =(D22*C22*F22) -> 3493.6192 | I22: 1262.9333 | J22: 345.33333 | K22: 202 | L22: =(I22+J22+K22) -> 1810.2667 | M22: =IF(M21>0,(M21+L22-H22),(L22-H22)) -> -1683.3525 | N22: -
B23: Apr'28 | C23: 19 | D23: =(D22*G23) -> 166.24227 | E23: =ROUND(D23*5/7,0) -> 119 | F23: 0.9 | G23: 0.985 | H23: =(D23*C23*F23) -> 2842.7428 | I23: 1459.3333 | J23: 480.53333 | K23: 228 | L23: =(I23+J23+K23) -> 2167.8667 | M23: =IF(M22>0,(M22+L23-H23),(L23-H23)) -> -674.87608 | N23: -
B24: May'28 | C24: 22 | D24: =(D23*G24) -> 163.74863 | E24: =ROUND(D24*5/7,0) -> 117 | F24: 0.9 | G24: 0.985 | H24: =(D24*C24*F24) -> 3242.2229 | I24: 525.2 | J24: 551.6 | K24: 112.26667 | L24: =(I24+J24+K24) -> 1189.0667 | M24: =IF(M23>0,(M23+L24-H24),(L24-H24)) -> -2053.1563 | N24: -
B25: Jun'28 | C25: 21 | D25: =(D24*G25) -> 161.2924 | E25: =ROUND(D25*5/7,0) -> 115 | F25: 0.9 | G25: 0.985 | H25: =(D25*C25*F25) -> 3048.4264 | I25: 689.33333 | J25: 671.73333 | K25: 173.73333 | L25: =(I25+J25+K25) -> 1534.8 | M25: =IF(M24>0,(M24+L25-H25),(L25-H25)) -> -1513.6264 | N25: -
B26: Jul'28 | C26: 21 | D26: =(D25*G26) -> 158.87302 | E26: =ROUND(D26*5/7,0) -> 113 | F26: 0.9 | G26: 0.985 | H26: =(D26*C26*F26) -> 3002.7 | I26: 724.93333 | J26: 710.8 | K26: 182.4 | L26: =(I26+J26+K26) -> 1618.1333 | M26: =IF(M25>0,(M25+L26-H26),(L26-H26)) -> -1384.5667 | N26: -
B27: Aug'28 | C27: 22 | D27: =(D26*G27) -> 156.48992 | E27: =ROUND(D27*5/7,0) -> 112 | F27: 0.9 | G27: 0.985 | H27: =(D27*C27*F27) -> 3098.5004 | I27: 217.2 | J27: 717.73333 | K27: 54.666667 | L27: =(I27+J27+K27) -> 989.6 | M27: =IF(M26>0,(M26+L27-H27),(L27-H27)) -> -2108.9004 | N27: -
B28: Sep'28 | C28: 20 | D28: =(D27*G28) -> 154.14257 | E28: =ROUND(D28*5/7,0) -> 110 | F28: 0.9 | G28: 0.985 | H28: =(D28*C28*F28) -> 2774.5663 | I28: 0 | J28: 1607.7333 | K28: 0 | L28: =(I28+J28+K28) -> 1607.7333 | M28: =IF(M27>0,(M27+L28-H28),(L28-H28)) -> -1166.833 | N28: Tentative Indonesia completion time (2-Sep-28)
B29: Oct'28 | C29: 20 | D29: =(D28*G29) -> 151.83043 | E29: =ROUND(D29*5/7,0) -> 108 | F29: 0.9 | G29: 0.985 | H29: =(D29*C29*F29) -> 2732.9478 | I29: 0 | J29: 1385.6 | K29: 0 | L29: =(I29+J29+K29) -> 1385.6 | M29: =IF(M28>0,(M28+L29-H29),(L29-H29)) -> -1347.3478 | N29: -
B30: Nov'28 | C30: 22 | D30: =(D29*G30) -> 149.55298 | E30: =ROUND(D30*5/7,0) -> 107 | F30: 0.9 | G30: 0.985 | H30: =(D30*C30*F30) -> 2961.149 | I30: 0 | J30: 529.06667 | K30: 0 | L30: =(I30+J30+K30) -> 529.06667 | M30: =IF(M29>0,(M29+L30-H30),(L30-H30)) -> -2432.0823 | N30: -
B31: Dec'28 | C31: 3 | D31: =(D30*G31) -> 147.30968 | E31: =ROUND(D31*5/7,0) -> 105 | F31: 0.9 | G31: 0.985 | H31: =(D31*C31*F31) -> 397.73614 | I31: 0 | J31: 0 | K31: 0 | L31: =(I31+J31+K31) -> 0 | M31: =IF(M30>0,(M30+L31-H31),(L31-H31)) -> -397.73614 | N31: Tentative Philippines completion time (7-Dec-28)
H32: Overall | I32: =SUM(I4:I31) -> 16454.267 | J32: =SUM(J4:J31) -> 33820.267 | K32: =SUM(K4:K31) -> 2102.4 | L32: Idle | M32: =SUMIF(M4:M31,"<0") -> -36772.784
B34: Pending effort | C34: =SUM(L4:L31) -> 52376.933
B35: Capacity available | C35: =SUM(H4:H31) -> 89149.718
B36: Idle Mandays | C36: =C35-C34 -> 36772.784
H56: last week pending efforts | I56: 106745
H57: Current week pending efforts | I57: 104632
H58: Variance | I58: =I56-I57 -> 2113
H59: Week consumption | I59: 1697
H60: Additionally lost effort due to Plan vs Actual & speed achievement | I60: 547
H61: Overall variance | I61: =I58-I59-I60 -> -131
...

Sheet HC Distribution
B2: Year | C2: Month | D2: HLA | E2: AdC | F2: MPRA | G2: Addressing Finishing (33) + FunT (15)+Aditional finishing(40) | H2: Addressing Overall HC | I2: Temporary Movement | J2: Remarks
B3: 2025 | C3: LTP 9/1 | D3: 50 | E3: 149.6 | F3: 117 | G3: 90 | H3: =SUM(D3:G3) -> 406.6
B4: 2025 | C4: LTP 9/8 | D4: 50 | E4: 149.6 | F4: 117 | G4: 90 | H4: =SUM(D4:G4) -> 406.6 | J4: Moving 42 HC (Additional) from Build to Finishing
B5: 2025 | C5: LTP 9/15 | D5: 50 | E5: 149.6 | F5: 117 | G5: 90 | H5: =SUM(D5:G5) -> 406.6 | J5: -
B6: 2025 | C6: LTP 9/22 | D6: 50 | E6: 149.6 | F6: 114 | G6: 90 | H6: =SUM(D6:G6) -> 403.6 | J6: -
B7: 2025 | C7: LTP 9/29 | D7: 50 | E7: 149.6 | F7: 114 | G7: 90 | H7: =SUM(D7:G7) -> 403.6 | J7: -
B8: 2025 | C8: LTP 10/6 | D8: 50 | E8: 150 | F8: 110 | G8: 90 | H8: =SUM(D8:G8) -> 400 | J8: -
B9: 2025 | C9: LTP 10/13 | D9: 50 | E9: 150 | F9: 110 | G9: 90 | H9: =SUM(D9:G9) -> 400 | J9: -
B10: 2025 | C10: LTP 10/20 | D10: 50 | E10: 150 | F10: 110 | G10: 90 | H10: =SUM(D10:G10) -> 400 | J10: -
B11: 2025 | C11: LTP 10/27 | D11: 50 | E11: 150 | F11: 110 | G11: 90 | H11: =SUM(D11:G11) -> 400 | J11: -
B12: 2025 | C12: LTP 11/3 | D12: 60 | E12: 150 | F12: 90 | G12: 90 | H12: 390 | J12: -
B13: 2025 | C13: LTP 11/10 | D13: 60 | E13: 150 | F13: 90 | G13: 90 | H13: 390 | J13: -
B14: 2025 | C14: LTP 11/17 | D14: 60 | E14: 150 | F14: 132 | G14: 48 | H14: 390 | J14: -
B15: 2025 | C15: LTP 11/24 | D15: 60 | E15: 150 | F15: 132 | G15: 48 | H15: 390 | J15: Bringing back 42 HC from Finishing to Build
B16: 2025 | C16: LTP 12/1 | D16: 50 | E16: 150 | F16: 152 | G16: 33 | H16: 385 | J16: There is no FunT work planned beyond Nov'25; Hence 15 HC included in Production Dec'25 onwards
B17: 2025 | C17: LTP 12/8 | D17: 50 | E17: 150 | F17: 152 | G17: 33 | H17: 385 | J17: There is no FunT work planned beyond Nov'25; Hence 15 HC included in Production Dec'25 onwards
B18: 2025 | C18: LTP 12/15 | D18: 50 | E18: 150 | F18: 152 | G18: 33 | H18: 385 | J18: -
B19: 2025 | C19: LTP 12/22 | D19: 50 | E19: 150 | F19: 152 | G19: 33 | H19: 385 | J19: -
B20: 2025 | C20: LTP 12/29 | D20: 50 | E20: 150 | F20: 152 | G20: 33 | H20: 385 | J20: India Completed by 31-Dec-2025
B21: 2025 | C21: LTP 1/5 | D21: 40 | E21: 150 | F21: 157 | G21: =33 -> 33 | H21: =SUM(D21:G21) -> 380 | J21: -
B22: 2025 | C22: LTP 1/12 | D22: 50 | E22: 180 | F22: 117 | G22: =33 -> 33 | H22: =SUM(D22:G22) -> 380 | J22: -
B23: 2025 | C23: LTP 1/19 | D23: 50 | E23: 180 | F23: 117 | G23: =33 -> 33 | H23: =SUM(D23:G23) -> 380 | J23: -
B24: 2026 | C24: LTP 1/26 | D24: 50 | E24: 180 | F24: 117 | G24: 33 | H24: =SUM(D24:G24) -> 380 | J24: -
B25: 2025 | C25: LTP 2/2 | D25: 80 | E25: 180 | F25: 82 | G25: 33 | H25: =SUM(D25:G25) -> 375 | J25: -
B26: 2025 | C26: LTP 2/9 | D26: 80 | E26: 180 | F26: 82 | G26: 33 | H26: 375 | J26: -
B27: 2025 | C27: LTP 2/16 | D27: 50 | E27: 120 | F27: 176 | G27: 33 | H27: =SUM(D27:G27) -> 379 | J27: -
B28: 2025 | C28: LTP 2/23 | D28: 50 | E28: 120 | F28: 176 | G28: 33 | H28: =SUM(D28:G28) -> 379
B29: 2026 | C29: LTP 3/2 | D29: 40 | E29: 120 | F29: 180 | G29: 33 | H29: =SUM(D29:G29) -> 373 | J29: -
B30: 2026 | C30: LTP 3/9 | D30: 40 | E30: 120 | F30: 180 | G30: 33 | H30: =SUM(D30:G30) -> 373 | J30: -
B31: 2026 | C31: LTP 3/16 | D31: 40 | E31: 120 | F31: 180 | G31: 33 | H31: =SUM(D31:G31) -> 373 | J31: -
B32: 2026 | C32: LTP 3/23 | D32: 40 | E32: 120 | F32: 180 | G32: 33 | H32: =SUM(D32:G32) -> 373 | J32: -
B33: 2026 | C33: LTP 3/30 | D33: 40 | E33: 120 | F33: 180 | G33: 33 | H33: =SUM(D33:G33) -> 373 | J33: -
B34: 2026 | C34: LTP 4/6 | D34: 40 | E34: 80 | F34: 215 | G34: 33 | H34: =SUM(D34:G34) -> 368 | J34: -
B35: 2026 | C35: LTP 4/20 | D35: 40 | E35: 80 | F35: 215 | G35: 33 | H35: =SUM(D35:G35) -> 368 | J35: -
B36: 2026 | C36: LTP 4/27 | D36: 40 | E36: 80 | F36: 215 | G36: 33 | H36: =SUM(D36:G36) -> 368 | J36: -
B37: 2026 | C37: LTP 5/4 | D37: 40 | E37: 80 | F37: 215 | G37: 33 | H37: =SUM(D37:G37) -> 368 | J37: -
B38: 2026 | C38: LTP 5/11 | D38: 50 | E38: 225 | F38: 0 | G38: 33 | H38: =SUM(D38:G38) -> 308 | J38: -
B39: 2026 | C39: LTP 5/18 | D39: 50 | E39: 50 | F39: 172 | G39: 33 | H39: =SUM(D39:G39) -> 305 | J39: -
B40: 2026 | C40: LTP 5/25 | D40: 50 | E40: 50 | F40: 172 | G40: 33 | H40: =SUM(D40:G40) -> 305 | J40: 57HC Movement, MPRA HC is engaged in IND product improvement
... B48: 2026 | C48: LTP 7/20 | D48: 25 | E48: 50 | F48: 120 | G48: 33 | H48: =SUM(D48:G48) -> 228 | J48: 20 HC moved to Additional Finishing Task 25 HC moved to QA temporarily
...

Sheet Inventory
B2: Last updated Date | C2: 46286
F3: In Pipeline from Upstream (Naming QA & DC2) | M3: Abbreviations | N3: Definition | P3: Status | Q3: Band (in days) | R3: Flag
B4: Category | C4: In Hand | D4: Pre-Rx | E4: In Pipeline | F4: Current Week (9/20 - 9/26) | G4: Current Week +1 (9/27 - 10/3) | H4: Current Week +2 (10/4 - 10/10) | I4: Current Week +3 (10/11 - 10/17) | M4: WIP | N4: Waves In Progress | P4: WIP | Q4: >2 | R4: Green
B5: Mandays | C5: =SUM(G21,G27) -> 2170 | D5: =SUM(H21,H27) -> 5450 | E5: =SUM(F5:I5) -> 3792 | F5: =SUMIFS($H$31:$H$33,$J$31:$J$33,F$4) -> 0 | G5: =SUMIFS($H$31:$H$33,$J$31:$J$33,G$4) -> 0 | H5: =SUMIFS($H$31:$H$33,$J$31:$J$33,H$4) -> 1507 | I5: =SUMIFS($H$31:$H$33,$J$31:$J$33,I$4) -> 2285 | M5: YTS | N5: Waves generated & yet to be picked | Q5: >1 - <=2 | R5: White
B6: Workdays | C6: =C5/$C$8 -> 9.8190045 | D6: =D5/$C$8 -> 24.660633 | E6: =E5/$C$8 -> 17.158371 | F6: =F5/$C$8 -> 0 | G6: =G5/$C$8 -> 0 | H6: =H5/$C$8 -> 6.8190045 | I6: =I5/$C$8 -> 10.339367 | M6: In Hand | N6: Total work in BRs available from upstream (depends on jobrun) | Q6: >0.5 - <=1 | R6: Amber
M7: In Hand- Blocked | N7: Work Available till phase end for the Blocked Waves (Due to Job issues / source unavailabilty) | Q7: <=0.5 | R7: Red
B8: HC | C8: 221 | M8: Current Week (Date range) | N8: Work expected from Naming QA and DCLG in the current Week
B9: 100% Utilization till (In Hand + Pre-Rx) | C9: =WORKDAY(C2,ROUNDDOWN(SUM(C6:D6),0))-1 -> 46331 | M9: Current Week +1 (Date range) | N9: Work expected from Naming QA and DCLG in the upcoming Week
M10: Current Week +2 (Date range) | N10: Work expected from Naming QA and DCLG in the upcoming 2nd week
B11: WIP & YTS BRs | M11: Current Week +3 (Date range) | N11: Work expected from Naming QA and DCLG in the upcoming 3rd week
B12: Region | C12: BR ID | D12: BR | E12: WIP wave | F12: Dependencies (If Any) | G12: WIP (Effort in Man-days) | H12: Effort pending till end of BV (In Man days)
B13: MPRA
B14: Brazil_P2 | C14: kh.br.sa.bra.08_A | D14: São Paulo | E14: MPRA BV ITR2 | F14: WIP | G14: 9 | H14: 0
B15: Brazil_P2 | C15: kh.br.sa.bra.11_A | D15: Rio de Janeiro | E15: Resnap HLA | F15: WIP | G15: 1 | H15: 395
B16: Brazil_P2 | C16: kh.br.sa.bra.11_C | D16: Vitória | E16: Ranges2 | F16: WIP | G16: 180 | H16: 300
B17: Brazil_P2 | C17: kh.br.sa.bra.11_B | D17: Campos dos Goytacazes | E17: Ranges2 | F17: WIP | G17: 307 | H17: 615
B18: Brazil_P2 | C18: kh.br.sa.bra.08_C | D18: Campinas | E18: Ranges2 | F18: WIP | G18: 232 | H18: 739
B19: Brazil_P2 | C19: kh.br.sa.bra.08_D | D19: Ribeirão Preto | E19: Merge | F19: YTS | G19: 43 | H19: 1474
B20: Brazil_P2 | C20: kh.br.sa.bra.08_B | D20: São José dos Campos | E20: Merge | F20: JIP | G20: 58 | H20: 1546
B21: Total | G21: =SUM(G14:G20) -> 830 | H21: =SUM(H14:H20) -> 5069
B22: HLA & ADC
B23: Brazil_P2 | C23: kh.br.sa.bra.06 | D23: Porto Alegre | E23: Unmatched | F23: YTS | G23: 794 | H23: 209
B24: Brazil_P2 | C24: kh.br.sa.bra.04 | D24: Cuiaba | E24: Unmatched | F24: YTS | G24: 236 | H24: 57
B25: Brazil_P2 | C25: kh.br.sa.bra.03 | D25: Belem | E25: HLA | F25: YTS | G25: 283 | H25: 81
B26: Brazil_P2 | C26: kh.br.sa.bra.02 | D26: Manaus | E26: HLA | F26: YTS | G26: 27 | H26: 34
B27: Total | G27: =SUM(G23:G26) -> 1340 | H27: =SUM(H23:H26) -> 381
B29: Expected per Plan (Naming QA & DC2)
B30: Region | C30: BR ID | D30: BR | E30: Blocked Wave | F30: Dependencies (If Any) | G30: WIP (Effort in Man-days) | H30: Effort pending till end of BV (In Man days) | I30: Expected Date | J30: Week Range | K30: Remarks
B31: Brazil_P2 | C31: kh.br.sa.bra.07_A | D31: Curitiba | E31: HLA & AdC Stage | F31: Naming QA | G31: - | H31: 1271 | I31: 46312 | J31: Current Week +3 (10/11 - 10/17) | K31: -
B32: Brazil_P2 | C32: kh.br.sa.bra.16 | D32: Salvador | E32: MPRA Stage | F32: DC2 | G32: - | H32: 1507 | I32: 46299 | J32: Current Week +2 (10/4 - 10/10) | K32: -
B33: Brazil_P2 | C33: kh.br.sa.bra.17 | D33: Recife | E33: MPRA Stage | F33: DC2 | G33: - | H33: 1014 | I33: 46307 | J33: Current Week +3 (10/11 - 10/17) | K33: -

Sheet Wave wise Effort
AV1: °–
Q2: Region | R2: Source Prep (mandays) | S2: HLA (mandays) | T2: ADC (mandays) | U2: MPRA (mandays) | V2: Overall Pending Effort (Mandays) | X2: Region | Y2: Source Prep (hours) | Z2: HLA (hours) | AA2: ADC (hours) | AB2: MPRA (hours) | AC2: Overall Pending Effort (hours)
A3: WIP | Q3: Brazil_P2 | R3: =SUMIF($A$11:$A$80,$Q3,K$11:K$80) -> 0 | S3: =SUMIF($A$11:$A$80,$Q3,L$11:L$80) -> 562 | T3: =SUMIF($A$11:$A$80,$Q3,M$11:M$80) -> 3489.7333 | U3: =SUMIF($A$11:$A$80,$Q3,N$11:N$80) -> 25647.067 | V3: =SUM(R3:U3) -> 29698.8 | X3: Brazil_P2 | Y3: =SUMIF($A$11:$A$80,$Q3,K$11:K$80)*7.5 -> 0 | Z3: =SUMIF($A$11:$A$80,$Q3,L$11:L$80)*7.5 -> 4215 | AA3: =SUMIF($A$11:$A$80,$Q3,M$11:M$80)*7.5 -> 26173 | AB3: =SUMIF($A$11:$A$80,$Q3,N$11:N$80)*7.5 -> 192353 | AC3: =SUM(Y3:AB3) -> 222741
